<robot name="hrp4_feet_fixed" xmlns:xacro="http://ros.org/wiki/xacro">

  <!-- right foot -->
  <joint name="RLEG_BUSH_Z" type="prismatic">
    <parent link="R_ANKLE_R_LINK"/>
    <child link="r_ankle_bush_1"/>
    <origin xyz="0 0 0" rpy="0 0 0"/>
    <axis xyz="0 0 1"/>
    <limit effort="10000.0" velocity="10000.0" lower="-1.0" upper="1.0" />
  </joint>

  <link name="r_ankle_bush_1">
    <inertial>
      <origin xyz="0.0 0.0 0.0" rpy="0 0 0"/>
      <mass value="0.0001"/>
      <inertia ixx="0.0001" ixy="0.0" ixz="0.0" iyy="0.0001" iyz="0.0" izz="0.00001"/>
    </inertial>
  </link>
  <joint name="RLEG_BUSH_ROLL" type="revolute">
    <parent link="r_ankle_bush_1"/>
    <child link="r_ankle_bush_2"/>
    <origin xyz="0 0 0" rpy="0 0 0"/>
    <axis xyz="1 0 0"/>
    <limit effort="10000.0" velocity="10000.0" lower="-3.14" upper="3.14" />
  </joint>

  <link name="r_ankle_bush_2">
    <inertial>
      <origin xyz="0.0 0.0 0.0" rpy="0 0 0"/>
      <mass value="0.0001"/>
      <inertia ixx="0.0001" ixy="0.0" ixz="0.0" iyy="0.0001" iyz="0.0" izz="0.00001"/>
    </inertial>
  </link>
  <joint name="RLEG_BUSH_PITCH" type="revolute">
    <parent link="r_ankle_bush_2"/>
    <child link="r_ankle"/>
    <origin xyz="0 0 0" rpy="0 0 0"/>
    <axis xyz="0 1 0"/>
    <limit effort="10000.0" velocity="10000.0" lower="-3.14" upper="3.14" />
  </joint>

  <link name="r_ankle">
    <inertial>
      <origin rpy="0 0 0" xyz="0.01130279 -0.01139641 -0.07868422"/>
      <mass value="0.57831553"/>
      <inertia ixx="0.00121526" ixy="8.51e-06" ixz="2.787e-05" iyy="0.00254705" iyz="-2.1e-06" izz="0.00362666"/>
    </inertial>
    <visual>
      <origin rpy="0 0 0" xyz="0 0 0"/>
      <geometry>
        <mesh filename="package://hrp4_description/meshes/R_FOOT.dae"/>
      </geometry>
    </visual>
    <collision>
      <origin rpy="0 0 0" xyz="0 0 0"/>
      <geometry>
        <mesh filename="package://hrp4_description/meshes/R_FOOT.dae"/>
      </geometry>
    </collision>
  </link>



  <!-- left foot -->
  <joint name="LLEG_BUSH_Z" type="prismatic">
    <parent link="L_ANKLE_R_LINK"/>
    <child link="l_ankle_bush_1"/>
    <origin xyz="0 0 0" rpy="0 0 0"/>
    <axis xyz="0 0 1"/>
    <limit effort="10000.0" velocity="10000.0" lower="-1.0" upper="1.0" />
  </joint>

  <link name="l_ankle_bush_1">
    <inertial>
      <origin xyz="0.0 0.0 0.0" rpy="0 0 0"/>
      <mass value="0.0001"/>
      <inertia ixx="0.0001" ixy="0.0" ixz="0.0" iyy="0.0001" iyz="0.0" izz="0.00001"/>
    </inertial>
  </link>
  <joint name="LLEG_BUSH_ROLL" type="revolute">
    <parent link="l_ankle_bush_1"/>
    <child link="l_ankle_bush_2"/>
    <origin xyz="0 0 0" rpy="0 0 0"/>
    <axis xyz="1 0 0"/>
    <limit effort="10000.0" velocity="10000.0" lower="-3.14" upper="3.14" />
  </joint>

  <link name="l_ankle_bush_2">
    <inertial>
      <origin xyz="0.0 0.0 0.0" rpy="0 0 0"/>
      <mass value="0.0001"/>
      <inertia ixx="0.0001" ixy="0.0" ixz="0.0" iyy="0.0001" iyz="0.0" izz="0.00001"/>
    </inertial>
  </link>
  <joint name="LLEG_BUSH_PITCH" type="revolute">
    <parent link="l_ankle_bush_2"/>
    <child link="l_ankle"/>
    <origin xyz="0 0 0" rpy="0 0 0"/>
    <axis xyz="0 1 0"/>
    <limit effort="10000.0" velocity="10000.0" lower="-3.14" upper="3.14" />
  </joint>

  <link name="l_ankle">
    <inertial>
      <origin rpy="0 0 0" xyz="0.01130279 0.01139641 -0.07868422"/>
      <mass value="0.57831553"/>
      <inertia ixx="0.00121526" ixy="-8.51e-06" ixz="2.787e-05" iyy="0.00254705" iyz="2.1e-06" izz="0.00362666"/>
    </inertial>
    <visual>
      <origin rpy="0 0 0" xyz="0 0 0"/>
      <geometry>
        <mesh filename="package://hrp4_description/meshes/L_FOOT.dae"/>
      </geometry>
    </visual>
    <collision>
      <origin rpy="0 0 0" xyz="0 0 0"/>
      <geometry>
        <mesh filename="package://hrp4_description/meshes/L_FOOT.dae"/>
      </geometry>
    </collision>
  </link>
</robot>
